<?xml version="1.0" ?>
<!-- =================================================================================== -->
<!-- |    This document was autogenerated by xacro from robot.xacro                    | -->
<!-- |    EDITING THIS FILE BY HAND IS NOT RECOMMENDED                                 | -->
<!-- =================================================================================== -->
<robot name="hector">
  <material name="black">
    <color rgba="0.0 0.0 0.0 1.0"/>
  </material>
  <material name="blue">
    <color rgba="0.0 0.0 0.8 1.0"/>
  </material>
  <material name="green">
    <color rgba="0.0 0.8 0.0 1.0"/>
  </material>
  <material name="grey">
    <color rgba="0.2 0.2 0.2 1.0"/>
  </material>
  <material name="silver">
    <color rgba="0.9137254901960784 0.9137254901960784 0.8470588235294118 1.0"/>
  </material>
  <material name="orange">
    <color rgba="1.0 0.4235294117647059 0.0392156862745098 1.0"/>
  </material>
  <material name="brown">
    <color rgba="0.8705882352941177 0.8117647058823529 0.7647058823529411 1.0"/>
  </material>
  <material name="red">
    <color rgba="0.8 0.0 0.0 1.0"/>
  </material>
  <material name="white">
    <color rgba="1.0 1.0 1.0 1.0"/>
  </material>
  <material name="gold">
    <color rgba="0.8313725490196079 0.6862745098039216 0.21568627450980393 1.0"/>
  </material>
  <!-- ros_control plugin -->

  <link name="base">
    <visual>
      <origin rpy="0 0 0" xyz="0 0 0"/>
      <geometry>
        <box size="0.001 0.001 0.001"/>
      </geometry>
    </visual>
  </link>
  <joint name="floating_base" type="fixed">
    <origin rpy="0 0 0" xyz="0 0 0"/>
    <parent link="base"/>
    <child link="trunk"/>
  </joint>
  <link name="trunk">
    <visual>
      <origin rpy="0 0 0" xyz="0 0 0"/>
      <geometry>
        <mesh filename="../meshes/body.stl" scale="1 1 1"/>
      </geometry>
      <material name="white"/>
    </visual>
    <collision>
      <origin rpy="0 0 0" xyz="0 0 0"/>
      <geometry>
        <mesh filename="../meshes/body.stl" scale="1 1 1"/>
      </geometry>
      <material name="white"/>
    </collision>
    <inertial>
      <origin rpy="0 0 0" xyz="0.0 0.003 -0.019"/>
      <mass value="4.78"/>
      <inertia ixx="0.0491667" ixy="0.000163" ixz="0.000263" iyy="0.042109" iyz="0.000161" izz="0.021437"/>
    </inertial>
  </link>
  <joint name="imu_joint" type="fixed">
    <parent link="trunk"/>
    <child link="imu_link"/>
    <origin rpy="0 0 0" xyz="0.1 0 0.11"/>
  </joint>
  <link name="imu_link">
    <inertial>
      <mass value="0.001"/>
      <origin rpy="0 0 0" xyz="0.0 0 0.0"/>
      <inertia ixx="0.0001" ixy="0" ixz="0" iyy="0.0001" iyz="0" izz="0.0001"/>
    </inertial>
    <visual>
      <origin rpy="0 0 0" xyz="0 0 0"/>
      <geometry>
        <box size="0.001 0.001 0.001"/>
      </geometry>
      <material name="red"/>
    </visual>
  </link>
  <!-- TODO: add inertial properties and update controller -->
  <joint name="head" type="fixed">
    <parent link="trunk"/>
    <child link="head_link"/>
    <origin rpy="0.0 0.0 0.0" xyz="0.0 0.0 0.12"/>
  </joint>
  <link name="head_link">
    <inertial>
      <mass value="0.001"/>
      <origin rpy="0 0 0" xyz="0 0 0"/>
      <inertia ixx="0.0001" ixy="0" ixz="0" iyy="0.0001" iyz="0" izz="0.0001"/>
    </inertial>
    <visual>
      <origin rpy="0 0 0" xyz="0 0 0"/>
      <geometry>
        <mesh filename="../meshes/Head.STL" scale="1.0 1.0 1.0"/>
      </geometry>
      <material name="red"/>
    </visual>
    <collision>
      <origin rpy="0 0 0" xyz="0 0 0"/>
      <geometry>
        <box size=".001 .001 .001"/>
      </geometry>
    </collision>
  </link>
  <joint name="L_hip_joint" type="revolute">
    <origin rpy="0 0 0" xyz="0.0 0.047 -0.1265"/>
    <parent link="trunk"/>
    <child link="L_hip"/>
    <axis xyz="0 0 1"/>
    <dynamics damping="0.0" friction="0.0"/>
    <limit effort="33.5" lower="-0.5235987755982988" upper="0.5235987755982988" velocity="21"/>
  </joint>
  <link name="L_hip">
    <visual>
      <origin rpy="0 0 0" xyz="0 0 0"/>
      <geometry>
        <mesh filename="../meshes/L_hip1.STL" scale="1 1 1"/>
      </geometry>
      <material name="orange"/>
    </visual>
    <collision>
      <origin rpy="0 0 0" xyz="0 0 0"/>
      <geometry>
        <mesh filename="../meshes/L_hip1.STL" scale="1 1 1"/>
      </geometry>
      <material name="orange"/>
    </collision>
    <inertial>
      <origin rpy="0 0 0" xyz="0.025109 -0.002292 -0.024732"/>
      <mass value="0.1733"/>
      <inertia ixx="0.00022" ixy="0.00001" ixz="-0.00006" iyy="0.00023" iyz="0.00001" izz="0.00016"/>
    </inertial>
  </link>
  <!--this link is only for motor mass&colllision-->
  <joint name="L_hip_trans_joint" type="fixed">
    <origin rpy="0 0 0" xyz="0.079 0.015 -0.0705"/>
    <parent link="L_hip"/>
    <child link="L_hip_trans"/>
  </joint>
  <link name="L_hip_trans">
    <inertial>
      <origin rpy="0 0 0" xyz="0 0 0"/>
      <mass value="0.65"/>
      <inertia ixx="0.00043875" ixy="0.0" ixz="0.0" iyy="0.00043875" iyz="0.0" izz="0.000658125"/>
    </inertial>
  </link>
  <joint name="L_hip_roll_joint" type="revolute">
    <origin rpy="0 0 0" xyz="0.0465 0.015 -0.0705"/>
    <parent link="L_hip"/>
    <child link="L_hip2"/>
    <axis xyz="1 0 0"/>
    <dynamics damping="0.0" friction="0.0"/>
    <limit effort="33.5" lower="-0.5235987755982988" upper="0.5235987755982988" velocity="21"/>
  </joint>
  <link name="L_hip2">
    <visual>
      <origin rpy="0 0 0" xyz="0 0 0"/>
      <geometry>
        <mesh filename="../meshes/L_hip2.STL" scale="1 1 1"/>
      </geometry>
      <material name="red"/>
    </visual>
    <collision>
      <origin rpy="0 0 0" xyz="0 0 0"/>
      <geometry>
        <mesh filename="../meshes/L_hip2.STL" scale="1 1 1"/>
      </geometry>
      <material name="red"/>
    </collision>

    <inertial>
      <origin rpy="0 0 0" xyz="-0.03 -0.009 0"/>
      <mass value="0.072"/>
      <inertia ixx="0.00004" ixy="0.0" ixz="0.0" iyy="0.0001" iyz="0.0" izz="0.00007"/>
    </inertial>
  </link>
  <!--this link is only for collision-->
  <joint name="L_hip2_trans_joint" type="fixed">
    <origin rpy="0 0 0" xyz="-0.06 -0.015 0.0"/>
    <parent link="L_hip2"/>
    <child link="L_hip2_trans"/>
  </joint>
  <link name="L_hip2_trans">
    <!-- <collision>
                <origin rpy="${-PI/2} 0 0" xyz="0 0 0"/>
                <geometry>
                    <cylinder length="${hip2_trans_length}" radius="${hip2_trans_radius}"/>
                </geometry>
            </collision> -->
    <inertial>
      <origin rpy="-1.5707963267948966 0 0" xyz="0 0 0"/>
      <mass value="0.65"/>
      <inertia ixx="0.00043875" ixy="0.0" ixz="0.0" iyy="0.00043875" iyz="0.0" izz="0.000658125"/>
    </inertial>
  </link>
  <joint name="L_thigh_joint" type="revolute">
    <!-- <origin rpy="0 0.7853981633974483 0" xyz="-0.06 0.018 0"/> -->
    <origin rpy="0 0.0 0" xyz="-0.06 0.018 0"/>
    <parent link="L_hip2"/>
    <child link="L_thigh"/>
    <axis xyz="0 1 0"/>
    <joint_properties damping="0.0" friction="0.0"/>
    <!-- <limit effort="${thigh_torque_max}" velocity="${thigh_velocity_max}"/> -->
    <limit effort="33.5" lower="0.0" upper="2.26"  velocity="21"/>
  </joint>
  <link name="L_thigh">
    <visual>
      <origin rpy="0 0 0" xyz="0 0 0"/>
      <geometry>
        <mesh filename="../meshes/thigh_combined_L2.stl" scale="1 1 1"/>
      </geometry>
      <material name="white"/>
    </visual>
    <collision>
      <origin rpy="0 0 0" xyz="0 0 0"/>
      <geometry>
        <mesh filename="../meshes/thigh_combined_L2.stl" scale="1 1 1"/>
      </geometry>
      <material name="white"/>
    </collision>
    <!-- <collision>
                <origin rpy="0 0 0" xyz="${thigh_x} ${thigh_y*mirror} ${thigh_z}"/>
                <geometry>
                    <box size="${thigh_length} ${thigh_width} ${thigh_height}"/>
                </geometry>
            </collision> -->
    <inertial>
      <origin rpy="0 0 0" xyz="-0.000147 0.01991 -0.081117"/>
      <mass value="0.348"/>
      <inertia ixx="0.00196" ixy="0.0" ixz="0.0" iyy="0.00215" iyz="0.0" izz="0.00032"/>
    </inertial>
  </link>
  <!--this link is only for collision-->
  <joint name="L_thigh1_trans_joint" type="fixed">
    <origin rpy="0 0 0" xyz="0.0 0.0625 0.0"/>
    <parent link="L_thigh"/>
    <child link="L_thigh1_trans"/>
  </joint>
  <link name="L_thigh1_trans">
    <!-- <collision>
                <origin rpy="${-PI/2} 0 0" xyz="0 0 0"/>
                <geometry>
                    <cylinder length="${thigh1_trans_length}" radius="${thigh1_trans_radius}"/>
                </geometry>
            </collision> -->
    <inertial>
      <origin rpy="-1.5707963267948966 0 0" xyz="0 0 0"/>
      <mass value="0.65"/>
      <inertia ixx="0.00043875" ixy="0.0" ixz="0.0" iyy="0.00043875" iyz="0.00002" izz="0.000658125"/>
    </inertial>
  </link>
  <!--this link is only for collision-->
  <joint name="L_thigh2_trans_joint" type="fixed">
    <origin rpy="0 0 0" xyz="0.0 -0.0225 -0.097"/>
    <parent link="L_thigh"/>
    <child link="L_thigh2_trans"/>
  </joint>
  <link name="L_thigh2_trans">
    <!-- <collision>
                <origin rpy="${-PI/2} 0 0" xyz="0 0 0"/>
                <geometry>
                    <cylinder length="${thigh2_trans_length}" radius="${thigh2_trans_radius}"/>
                </geometry>
            </collision> -->
    <inertial>
      <origin rpy="-1.5707963267948966 0 0" xyz="0 0 0"/>
      <mass value="0.65"/>
      <inertia ixx="0.00043875" ixy="0.0" ixz="0.0" iyy="0.00043875" iyz="0.0" izz="0.000658125"/>
    </inertial>
  </link>
  <joint name="L_calf_joint" type="revolute">
    <origin rpy="0 0.0 0" xyz="0.0 0.0142 -0.22"/>

    <parent link="L_thigh"/>
    <child link="L_calf"/>
    <axis xyz="0 1 0"/>
    <joint_properties damping="0.0" friction="0.0"/>
    <limit effort="67" lower="-2.26" upper="0.0" velocity="10.5"/>
  </joint>
  <link name="L_calf">
    <visual>
      <origin rpy="0 0 0" xyz="0.0 0.0 -0.11"/>
      <geometry>
       <cylinder length="0.2" radius="0.015"/>
        <!-- <mesh filename="../meshes/calf_combined_L.stl" scale="1 1 1"/> -->
      </geometry>
      <material name="orange"/>
    </visual>
    <!-- <collision>
      <origin rpy="0 0 0" xyz="0.0 0.0 -0.11"/>
      <geometry>
        <cylinder length="0.2" radius="0.015"/>
      </geometry>
    </collision> -->
    <inertial>
      <origin rpy="0 0 0" xyz="0.00204 0.0 -0.07668"/>
      <mass value="0.14647"/>
      <inertia ixx="0.00074" ixy="0.0" ixz="0.0" iyy="0.00075" iyz="0.0" izz="0.00002"/>
    </inertial>
  </link>
  <joint name="L_toe_joint" type="revolute">
    <origin rpy="0 0.0 0" xyz="0.0 0.0 -0.22"/>
    <parent link="L_calf"/>
    <child link="L_toe"/>
    <axis xyz="0 1 0"/>
    <joint_properties damping="0.0" friction="0.0"/>
    <limit effort="33.5" lower="-1.4" upper="1.4" velocity="21"/>
  </joint>
  <link name="L_toe">
    <visual>
      <origin rpy="0 0 0" xyz="0 0 0"/>
      <geometry>
        <mesh filename="../meshes/Foot.STL" scale="1 1 1"/>
      </geometry>
      <material name="red"/>
    </visual>
    <collision>
          <origin rpy="0 0 0" xyz="0.02 0 -0.03"/>
                <geometry>
                     <box size="0.14 0.03 0.02"/>
                </geometry>      
    </collision>
    <!-- <collision>
      <origin rpy="0 0 0" xyz="0 0 0"/>
      <geometry>
        <mesh filename="../meshes/Foot.STL" scale="1 1 1"/>
      </geometry>
      <material name="red"/>
    </collision> -->
    <inertial>
      <origin rpy="0 0 0" xyz="0.010569 0.017949 -0.017118"/>
      <mass value="0.085"/>
      <inertia ixx="0.00006" ixy="0.0" ixz="0.0" iyy="0.00016" iyz="0.0" izz="0.00011"/>
    </inertial>
  </link>
  
  <joint name="R_hip_joint" type="revolute">
    <origin rpy="0 0 0" xyz="0.0 -0.047 -0.1265"/>
    <parent link="trunk"/>
    <child link="R_hip"/>
    <axis xyz="0 0 1"/>
    <dynamics damping="0.0" friction="0.0"/>
    <limit effort="33.5" lower="-0.5235987755982988" upper="0.5235987755982988" velocity="21"/>
  </joint>
  <link name="R_hip">
    <visual>
      <origin rpy="0 0 0" xyz="0 0 0"/>
      <geometry>
        <mesh filename="../meshes/R_hip1.STL" scale="1 1 1"/>
      </geometry>
      <material name="orange"/>
    </visual>
    <collision>
      <origin rpy="0 0 0" xyz="0 0 0"/>
      <geometry>
        <mesh filename="../meshes/R_hip1.STL" scale="1 1 1"/>
      </geometry>
      <material name="orange"/>
    </collision>
    <!-- <collision>
                <origin rpy="0 0 0" xyz="${hip_x} ${hip_y} ${hip_z}"/>
                <geometry>
                    <box size="${hip_length} ${hip_width} ${hip_height}"/>
                </geometry>
            </collision> -->
    <inertial>
      <origin rpy="0 0 0" xyz="0.025109 -0.002292 -0.024732"/>
      <mass value="0.1733"/>
      <inertia ixx="0.00022" ixy="-0.00001" ixz="-0.00006" iyy="0.00023" iyz="0.0" izz="0.00016"/>
    </inertial>
  </link>
  <!--this link is only for motor mass&colllision-->
  <joint name="R_hip_trans_joint" type="fixed">
    <origin rpy="0 0 0" xyz="0.079 -0.015 -0.0705"/>
    <parent link="R_hip"/>
    <child link="R_hip_trans"/>
  </joint>
  <link name="R_hip_trans">
    <!-- <collision>
                <origin rpy="0 ${PI/2} 0" xyz="0 0 0"/>
                <geometry>
                    <cylinder length="${hip_trans_length}" radius="${hip_trans_radius}"/>
                </geometry>
            </collision> -->
    <inertial>
      <origin rpy="0 0 0" xyz="0 0 0"/>
      <mass value="0.65"/>
      <inertia ixx="0.00043875" ixy="0.0" ixz="0.0" iyy="0.00043875" iyz="0.0" izz="0.000658125"/>
    </inertial>
  </link>
  <joint name="R_hip_roll_joint" type="revolute">
    <origin rpy="0 0 0" xyz="0.0465 -0.015 -0.0705"/>
    <parent link="R_hip"/>
    <child link="R_hip2"/>
    <axis xyz="1 0 0"/>
    <dynamics damping="0.0" friction="0.0"/>
    <limit effort="33.5" lower="-0.5235987755982988" upper="0.5235987755982988" velocity="21"/>
  </joint>
  <link name="R_hip2">
    <visual>
      <origin rpy="0 0 0" xyz="0 0 0"/>
      <geometry>
        <mesh filename="../meshes/R_hip2.STL" scale="1 1 1"/>
      </geometry>
      <material name="red"/>
    </visual>
    <collision>
      <origin rpy="0 0 0" xyz="0 0 0"/>
      <geometry>
        <mesh filename="../meshes/R_hip2.STL" scale="1 1 1"/>
      </geometry>
      <material name="red"/>
    </collision>
    <!-- <collision>
                <origin rpy="0 0 0" xyz="-0.1 0 0"/>
                <geometry>
                    <box size="${hip2_length} ${hip2_width} ${hip2_height}"/>
                </geometry>
            </collision> -->
    <inertial>
      <origin rpy="0 0 0" xyz="-0.03 -0.00942 0"/>
      <mass value="0.072"/>
      <inertia ixx="0.00004" ixy="0.0" ixz="0.0" iyy="0.0001" iyz="0.0" izz="0.00007"/>
    </inertial>
  </link>
  <!--this link is only for collision-->
  <joint name="R_hip2_trans_joint" type="fixed">
    <origin rpy="0 0 0" xyz="-0.06 0.015 0.0"/>
    <parent link="R_hip2"/>
    <child link="R_hip2_trans"/>
  </joint>
  <link name="R_hip2_trans">
    <!-- <collision>
                <origin rpy="${-PI/2} 0 0" xyz="0 0 0"/>
                <geometry>
                    <cylinder length="${hip2_trans_length}" radius="${hip2_trans_radius}"/>
                </geometry>
            </collision> -->
    <inertial>
      <origin rpy="-1.5707963267948966 0 0" xyz="0 0 0"/>
      <mass value="0.65"/>
      <inertia ixx="0.00043875" ixy="0.0" ixz="0.0" iyy="0.00043875" iyz="0.0" izz="0.000658125"/>
    </inertial>
  </link>
  <joint name="R_thigh_joint" type="revolute">
    <!-- <origin rpy="0 0.7853981633974483 0" xyz="-0.06 -0.018 0"/> -->
    <origin rpy="0 0.0 0" xyz="-0.06 -0.018 0"/>
    <parent link="R_hip2"/>
    <child link="R_thigh"/>
    <axis xyz="0 1 0"/>
    <joint_properties damping="0.0" friction="0.0"/>
    <!-- <limit effort="${thigh_torque_max}" velocity="${thigh_velocity_max}"/> -->
    <limit effort="33.5" lower="0.0" upper="2.26" velocity="21"/>
  </joint>
  <link name="R_thigh">
    <visual>
      <origin rpy="0 0 0" xyz="0 0 0"/>
      <geometry>
        <mesh filename="../meshes/thigh_combined_R2.stl" scale="1 1 1"/>
      </geometry>
      <material name="white"/>
    </visual>
    <collision>
      <origin rpy="0 0 0" xyz="0 0 0"/>
      <geometry>
        <mesh filename="../meshes/thigh_combined_R2.stl" scale="1 1 1"/>
      </geometry>
      <material name="white"/>
    </collision>
    <!-- <collision>
                <origin rpy="0 0 0" xyz="${thigh_x} ${thigh_y*mirror} ${thigh_z}"/>
                <geometry>
                    <box size="${thigh_length} ${thigh_width} ${thigh_height}"/>
                </geometry>
            </collision> -->
    <inertial>
      <origin rpy="0 0 0" xyz="0.000 -0.020891 -0.07506"/>
      <mass value="0.34806"/>
      <inertia ixx="0.00196" ixy="0.0" ixz="0.0" iyy="0.00215" iyz="0.0" izz="0.00032"/>
    </inertial>
  </link>
  <!--this link is only for collision-->
  <joint name="R_thigh1_trans_joint" type="fixed">
    <origin rpy="0 0 0" xyz="0.0 -0.0625 0.0"/>
    <parent link="R_thigh"/>
    <child link="R_thigh1_trans"/>
  </joint>
  <link name="R_thigh1_trans">
    <!-- <collision>
                <origin rpy="${-PI/2} 0 0" xyz="0 0 0"/>
                <geometry>
                    <cylinder length="${thigh1_trans_length}" radius="${thigh1_trans_radius}"/>
                </geometry>
            </collision> -->
    <inertial>
      <origin rpy="-1.5707963267948966 0 0" xyz="0 0 0"/>
      <mass value="0.65"/>
      <inertia ixx="0.00043875" ixy="0.0" ixz="0.0" iyy="0.00043875" iyz="0.0" izz="0.000658125"/>
    </inertial>
  </link>
  <!--this link is only for collision-->
  <joint name="R_thigh2_trans_joint" type="fixed">
    <origin rpy="0 0 0" xyz="0.0 0.0225 -0.097"/>
    <parent link="R_thigh"/>
    <child link="R_thigh2_trans"/>
  </joint>
  <link name="R_thigh2_trans">
    <!-- <collision>
                <origin rpy="${-PI/2} 0 0" xyz="0 0 0"/>
                <geometry>
                    <cylinder length="${thigh2_trans_length}" radius="${thigh2_trans_radius}"/>
                </geometry>
            </collision> -->
    <inertial>
      <origin rpy="-1.5707963267948966 0 0" xyz="0 0 0"/>
      <mass value="0.65"/>
      <inertia ixx="0.00043875" ixy="0.0" ixz="0.0" iyy="0.00043875" iyz="0.0" izz="0.000658125"/>
    </inertial>
  </link>
  <joint name="R_calf_joint" type="revolute">
    <origin rpy="0 0 0" xyz="0.0 -0.0142 -0.22"/>
    <parent link="R_thigh"/>
    <child link="R_calf"/>
    <axis xyz="0 1 0"/>
    <joint_properties damping="0.0" friction="0.0"/>
    <limit effort="67" lower="-2.26" upper="0.0" velocity="10.5"/>
  </joint>
  <link name="R_calf">
    <visual>
      <origin rpy="0 0 0" xyz="0.0 0.0 -0.11"/>
      <!-- R_calf.STL -->
                
      <geometry>
       <cylinder length="0.2" radius="0.015"/>
        <!-- <mesh filename="../meshes/calf_combined_R.stl" scale="1 1 1"/> -->
      </geometry>
      <material name="orange"/>
    </visual>
    <!-- <collision>
      <origin rpy="0 0 0" xyz="0.0 0.0 -0.11"/>
      <geometry>
        <cylinder length="0.2" radius="0.015"/>
      </geometry>
    </collision> -->
    <inertial>
      <origin rpy="0 0 0" xyz="0.00204 0.0 -0.07668"/>
      <mass value="0.14647"/>
      <inertia ixx="0.00074" ixy="0.0" ixz="0.0" iyy="0.00075" iyz="0.0" izz="0.00002"/>
    </inertial>
  </link>
  <joint name="R_toe_joint" type="revolute">
    <origin rpy="0 0.0 0" xyz="0.0 0.0 -0.22"/>
    <parent link="R_calf"/>
    <child link="R_toe"/>
    <axis xyz="0 1 0"/>
    <joint_properties damping="0.0" friction="0.0"/>
    <limit effort="33.5" lower="-1.4" upper="1.4" velocity="21"/>
  </joint>
  <link name="R_toe">
    <visual>
      <origin rpy="0 0 0" xyz="0 0 0"/>
      <geometry>
        <mesh filename="../meshes/Foot.STL" scale="1 1 1"/>
      </geometry>
      <material name="red"/>
    </visual>
    <collision>
          <origin rpy="0 0 0" xyz="0.02 0 -0.03"/>
                <geometry>
                     <box size="0.14 0.03 0.02"/>
                </geometry>      
    </collision>
    <!-- <collision>
      <origin rpy="0 0 0" xyz="0 0 0"/>
      <geometry>
        <mesh filename="../meshes/Foot.STL" scale="1 1 1"/>
      </geometry>
      <material name="red"/>
    </collision> -->
    <inertial>
      <origin rpy="0 0 0" xyz="0.010569 -0.017949 -0.017118"/>
      <mass value="0.085"/>
      <inertia ixx="0.00006" ixy="0.0" ixz="0.0" iyy="0.00016" iyz="0.0" izz="0.00011"/>
    </inertial>
  </link>
 
  <joint name="L_twist_joint" type="fixed">
    <origin rpy="0 0 0" xyz="0.0 -0.053 0.124"/>
    <!-- <xacro:if value="${(mirror_dae == True)}">
            <origin rpy="0 0 0" xyz="0.0 0.0 0.0"/>
            </xacro:if>
            
            <xacro:if value="${(mirror_dae == False)}">
            <origin rpy="0 0 0" xyz="0.0 0.0 0.0"/>
            </xacro:if>           -->
    <parent link="trunk"/>
    <child link="L_twist"/>
    <axis xyz="0 0 1"/>
    <!-- <dynamics damping="0.0" friction="0.0"/>
    <limit effort="33.5" lower="-1.4" upper="1.4" velocity="21"/> -->
  </joint>
  <link name="L_twist">
    <visual>
      <origin rpy="0 0 0" xyz="0 0 0"/>
      <geometry>
        <mesh filename="../meshes/hector_arm/ShoulderYaw_R.stl" scale="1 1 1"/>
      </geometry>
      <material name="orange"/>
    </visual>
    <collision>
      <origin rpy="0 0 0" xyz="0 0 0"/>
      <geometry>
        <mesh filename="../meshes/hector_arm/ShoulderYaw_R.stl" scale="1 1 1"/>
      </geometry>
      <material name="orange"/>
    </collision>
    <!-- <collision>
                <origin rpy="${PI/2.0} 0 0" xyz="0 ${-(twist_length/2.0-twist_offset)*mirror} 0"/>
                <geometry>
                    <cylinder length="${twist_length}" radius="${twist_radius}"/>
                </geometry>
            </collision> -->
    <inertial>
      <origin rpy="0 0 0" xyz="-0.0294 0.04541 0.00089"/>
      <mass value="0.432"/>
      <inertia ixx="0.00042" ixy="-2e-05" ixz="0.0" iyy="0.00027" iyz="0.0" izz="0.00033"/>
    </inertial>
    <!-- <inertial>
            <origin rpy="0 0 0" xyz="0.025109 -0.002292 -0.024732"/>
            <mass value="0.1"/>
            <inertia ixx="2.104e-02" ixy="0.0" ixz="0.0" iyy="5.354e-02" iyz="0.0" izz="7.416e-02"/>
            </inertial> -->
  </link>
  <joint name="L_shoulder_joint" type="fixed">
    <origin rpy="0 0 0" xyz="0.0 -0.049 0.053"/>
    <parent link="L_twist"/>
    <child link="L_shoulder"/>
    <axis xyz="0 1 0"/>
    <!-- <dynamics damping="0.0" friction="0.0"/>
    <limit effort="17" lower="-3.14" upper="1.5708" velocity="33"/> -->
  </joint>
  <link name="L_shoulder">
    <visual>
      <origin rpy="0 0 0" xyz="0 0 0"/>
      <geometry>
        <mesh filename="../meshes/hector_arm/ShoulderPitch_R.stl" scale="1 1 1"/>
      </geometry>
      <material name="gold"/>
    </visual>
    <collision>
      <origin rpy="0 0 0" xyz="0 0 0"/>
      <geometry>
        <mesh filename="../meshes/hector_arm/ShoulderPitch_R.stl" scale="1 1 1"/>
      </geometry>
      <material name="gold"/>
    </collision>
    <!-- <collision>
                <origin rpy="0 ${PI/2.0} 0" xyz="0 0 ${-shoulder_pitch_length/2.0}"/>
            <geometry>
                    <box size="${shoulder_pitch_length} ${shoulder_pitch_width} ${shoulder_pitch_height}"/>
                </geometry>      
            </collision> -->
    <inertial>
      <origin rpy="0 0 0" xyz="-0.0294 0.04541 0.00089"/>
      <mass value="0.432"/>
      <inertia ixx="0.00042" ixy="-2e-05" ixz="0.0" iyy="0.00027" iyz="0.0" izz="0.00033"/>
    </inertial>
  </link>
  <joint name="L_roll_joint" type="fixed">
    <origin rpy="0 0 0" xyz="-0.011 -0.0457 0.0"/>
    <parent link="L_shoulder"/>
    <child link="L_roll"/>
    <axis xyz="1 0 0"/>
    <!-- <dynamics damping="0.0" friction="0.0"/>
    <limit effort="17" lower="-1.4" upper="1.4" velocity="33"/> -->
    <!--<xacro:if value="${(mirror_dae == True)}">
                <limit effort="${shoulder_torque_max}" velocity="${shoulder_velocity_max}" lower="${shoulder_min}" upper="${shoulder_max}"/>
            </xacro:if>
            <xacro:if value="${(mirror_dae == False)}">
                <limit effort="${shoulder_torque_max}" velocity="${shoulder_velocity_max}" lower="${-shoulder_min}" upper="${-shoulder_max}"/>
            </xacro:if>-->
  </joint>
  <link name="L_roll">
    <visual>
      <origin rpy="0 0 0" xyz="0 0 0"/>
      <geometry>
        <mesh filename="../meshes/hector_arm/UpperArmRoll_R.stl" scale="1 1 1"/>
      </geometry>
      <material name="orange"/>
    </visual>
    <collision>
      <origin rpy="0 0 0" xyz="0 0 0"/>
      <geometry>
        <mesh filename="../meshes/hector_arm/UpperArmRoll_R.stl" scale="1 1 1"/>
      </geometry>
      <material name="orange"/>
    </collision>
    <!-- <collision>
                    <origin rpy="0 ${PI/2.0} 0" xyz="${shoulder_roll_offset_x} 0 ${-shoulder_roll_length/2.0}"/>
            <geometry>
                    <box size="${shoulder_roll_length} ${shoulder_roll_width} ${shoulder_roll_height}"/>
                </geometry>      
            </collision> -->
    <inertial>
      <origin rpy="0 0 0" xyz="0.04492 0.01006 -0.03218"/>
      <mass value="0.66484"/>
      <inertia ixx="0.00318" ixy="1e-05" ixz="0.0" iyy="0.00325" iyz="0.00037" izz="0.00049"/>
    </inertial>
  </link>
  <joint name="L_elbow_joint" type="fixed">
    <origin rpy="0 -1.5 0" xyz="0.041 0.007 -0.2"/>
    <parent link="L_roll"/>
    <child link="L_elbow"/>
    <axis xyz="0 1 0"/>
    <!-- <dynamics damping="0.0" friction="0.0"/>
    <limit effort="33.5" lower="-1.4" upper="1.4" velocity="21"/> -->
  </joint>
  <link name="L_elbow">
    <visual>
      <origin rpy="0 0 0" xyz="0 0 0"/>
      <geometry>
        <mesh filename="../meshes/hector_arm/ForeArmPitch.stl" scale="1 1 1"/>
      </geometry>
      <material name="gold"/>
    </visual>
    <collision>
      <origin rpy="0 0 0" xyz="0 0 0"/>
      <geometry>
        <mesh filename="../meshes/hector_arm/ForeArmPitch.stl" scale="1 1 1"/>
      </geometry>
      <material name="gold"/>
    </collision>
    <!-- <collision>
                <origin rpy="0 ${PI/2.0} 0" xyz="0 0 ${-elbow_length/2.0}"/>
                <geometry>
                    <box size="${elbow_length} ${elbow_width} ${elbow_height}"/>
                </geometry>      
            </collision> -->
    <inertial>
      <origin rpy="0 0 0" xyz="0.0 8e-05 -0.11722"/>
      <mass value="0.1578"/>
      <inertia ixx="0.00129" ixy="0.0" ixz="0.0" iyy="0.0013" iyz="0.0" izz="2e-05"/>
    </inertial>
  </link>

  <joint name="R_twist_joint" type="fixed">
    <origin rpy="0 0 0" xyz="0.0 0.053 0.124"/>
    <!-- <xacro:if value="${(mirror_dae == True)}">
            <origin rpy="0 0 0" xyz="0.0 0.0 0.0"/>
            </xacro:if>
            
            <xacro:if value="${(mirror_dae == False)}">
            <origin rpy="0 0 0" xyz="0.0 0.0 0.0"/>
            </xacro:if>           -->
    <parent link="trunk"/>
    <child link="R_twist"/>
    <axis xyz="0 0 1"/>
    <!-- <dynamics damping="0.0" friction="0.0"/>
    <limit effort="33.5" lower="-1.4" upper="1.4" velocity="21"/> -->
  </joint>
  <link name="R_twist">
    <!--
            <origin rpy="0 ${-PI/2.0} 0" xyz="0 0 0"/>
            <geometry>
                <mesh filename="../meshes/hip_a1.dae" scale="1 1 1"/>
            </geometry>
             -->
    <visual>
      <origin rpy="0 0 0" xyz="0 0 0"/>
      <geometry>
        <mesh filename="../meshes/hector_arm/ShoulderYaw_L.stl" scale="1 1 1"/>
      </geometry>
      <material name="orange"/>
    </visual>
    <collision>
      <origin rpy="0 0 0" xyz="0 0 0"/>
      <geometry>
        <mesh filename="../meshes/hector_arm/ShoulderYaw_L.stl" scale="1 1 1"/>
      </geometry>
      <material name="orange"/>
    </collision>
    <!-- <collision>
                <origin rpy="${PI/2.0} 0 0" xyz="0 ${-(twist_length/2.0-twist_offset)*mirror} 0"/>
                <geometry>
                    <cylinder length="${twist_length}" radius="${twist_radius}"/>
                </geometry>
            </collision> -->
    <inertial>
      <origin rpy="0 0 0" xyz="-0.0294 -0.04541 0.00089"/>
      <mass value="0.432"/>
      <inertia ixx="0.00042" ixy="2e-05" ixz="0.0" iyy="0.00027" iyz="-0.0" izz="0.00033"/>
    </inertial>
    <!-- <inertial>
            <origin rpy="0 0 0" xyz="0.025109 -0.002292 -0.024732"/>
            <mass value="0.1"/>
            <inertia ixx="2.104e-02" ixy="0.0" ixz="0.0" iyy="5.354e-02" iyz="0.0" izz="7.416e-02"/>
            </inertial> -->
  </link>
  <joint name="R_shoulder_joint" type="fixed">
    <origin rpy="0 0 0" xyz="0.0 0.049 0.053"/>
    <parent link="R_twist"/>
    <child link="R_shoulder"/>
    <axis xyz="0 1 0"/>
    <!-- <dynamics damping="0.0" friction="0.0"/>
    <limit effort="17" lower="-3.14" upper="1.5708" velocity="33"/> -->
  </joint>
  <link name="R_shoulder">
    <visual>
      <origin rpy="0 0 0" xyz="0 0 0"/>
      <geometry>
        <mesh filename="../meshes/hector_arm/ShoulderPitch_L.stl" scale="1 1 1"/>
      </geometry>
      <material name="gold"/>
    </visual>
    <collision>
      <origin rpy="0 0 0" xyz="0 0 0"/>
      <geometry>
        <mesh filename="../meshes/hector_arm/ShoulderPitch_L.stl" scale="1 1 1"/>
      </geometry>
      <material name="gold"/>
    </collision>
    <!-- <collision>
                <origin rpy="0 ${PI/2.0} 0" xyz="0 0 ${-shoulder_pitch_length/2.0}"/>
            <geometry>
                    <box size="${shoulder_pitch_length} ${shoulder_pitch_width} ${shoulder_pitch_height}"/>
                </geometry>      
            </collision> -->
    <inertial>
      <origin rpy="0 0 0" xyz="-0.0294 -0.04541 0.00089"/>
      <mass value="0.432"/>
      <inertia ixx="0.00042" ixy="2e-05" ixz="0.0" iyy="0.00027" iyz="-0.0" izz="0.00033"/>
    </inertial>
  </link>
  <joint name="R_roll_joint" type="fixed">
    <origin rpy="0 0 0" xyz="-0.011 0.0457 0.0"/>
    <parent link="R_shoulder"/>
    <child link="R_roll"/>
    <axis xyz="1 0 0"/>
    <!-- <dynamics damping="0.0" friction="0.0"/>
    <limit effort="17" lower="-1.4" upper="1.4" velocity="33"/> -->
    <!--<xacro:if value="${(mirror_dae == True)}">
                <limit effort="${shoulder_torque_max}" velocity="${shoulder_velocity_max}" lower="${shoulder_min}" upper="${shoulder_max}"/>
            </xacro:if>
            <xacro:if value="${(mirror_dae == False)}">
                <limit effort="${shoulder_torque_max}" velocity="${shoulder_velocity_max}" lower="${-shoulder_min}" upper="${-shoulder_max}"/>
            </xacro:if>-->
  </joint>
  <link name="R_roll">
    <visual>
      <origin rpy="0 0 0" xyz="0 0 0"/>
      <geometry>
        <mesh filename="../meshes/hector_arm/UpperArmRoll_L.stl" scale="1 1 1"/>
      </geometry>
      <material name="orange"/>
    </visual>
    <collision>
      <origin rpy="0 0 0" xyz="0 0 0"/>
      <geometry>
        <mesh filename="../meshes/hector_arm/UpperArmRoll_L.stl" scale="1 1 1"/>
      </geometry>
      <material name="orange"/>
    </collision>
    <!-- <collision>
                    <origin rpy="0 ${PI/2.0} 0" xyz="${shoulder_roll_offset_x} 0 ${-shoulder_roll_length/2.0}"/>
            <geometry>
                    <box size="${shoulder_roll_length} ${shoulder_roll_width} ${shoulder_roll_height}"/>
                </geometry>      
            </collision> -->
    <inertial>
      <origin rpy="0 0 0" xyz="0.04492 -0.01006 -0.03218"/>
      <mass value="0.66484"/>
      <inertia ixx="0.00318" ixy="-1e-05" ixz="0.0" iyy="0.00325" iyz="-0.00037" izz="0.00049"/>
    </inertial>
  </link>
  <joint name="R_elbow_joint" type="fixed">
    <origin rpy="0 -1.5 0" xyz="0.041 -0.007 -0.2"/>
    <parent link="R_roll"/>
    <child link="R_elbow"/>
    <axis xyz="0 1 0"/>
    <!-- <dynamics damping="0.0" friction="0.0"/>
    <limit effort="33.5" lower="-1.4" upper="1.4" velocity="21"/> -->
  </joint>
  <link name="R_elbow">
    <visual>
      <origin rpy="0 0 0" xyz="0 0 0"/>
      <geometry>
        <mesh filename="../meshes/hector_arm/ForeArmPitch.stl" scale="1 1 1"/>
      </geometry>
      <material name="gold"/>
    </visual>
    <collision>
      <origin rpy="0 0 0" xyz="0 0 0"/>
      <geometry>
        <mesh filename="../meshes/hector_arm/ForeArmPitch.stl" scale="1 1 1"/>
      </geometry>
      <material name="gold"/>
    </collision>
    <!-- <collision>
                <origin rpy="0 ${PI/2.0} 0" xyz="0 0 ${-elbow_length/2.0}"/>
                <geometry>
                    <box size="${elbow_length} ${elbow_width} ${elbow_height}"/>
                </geometry>      
            </collision> -->
    <inertial>
      <origin rpy="0 0 0" xyz="0.0 8e-05 -0.11722"/>
      <mass value="0.1578"/>
      <inertia ixx="0.00129" ixy="0.0" ixz="0.0" iyy="0.0013" iyz="0.0" izz="2e-05"/>
    </inertial>
  </link>
</robot>