<?xml version="1.0" ?>
<robot name="m1">

  <mujoco>
    <compiler meshdir="meshes" discardvisual="false"/>
  </mujoco>

  <!-- [CAUTION] uncomment when convert to mujoco -->
  <link name="world"></link>
  <joint name="floating_base_joint" type="floating">
    <parent link="world"/>
    <child link="pelvis"/>
  </joint>

  <link
    name="pelvis">
    <inertial>
      <origin
        xyz="-5E-05 -6E-05  -0.06266"
        rpy="0 0 0" />
      <mass value="3.2817" />
      <inertia
        ixx="0.01348"
        ixy="-1E-05"
        ixz="-1E-05"
        iyy="0.00852"
        iyz="-1E-05"
        izz="0.01379" />
    </inertial>
    <visual>
      <origin
        xyz="0 0 0"
        rpy="0 0 0" />
      <geometry>
        <mesh
          filename="meshes/pelvis.STL" />
      </geometry>
      <material
        name="">
        <color
          rgba="0.752941176470588 0.752941176470588 0.752941176470588 1" />
      </material>
    </visual>
    <collision>
      <origin
        xyz="0 0 0"
        rpy="0 0 0" />
      <geometry>
        <mesh
          filename="meshes/pelvis.STL" />
      </geometry>
    </collision>
  </link>

 <link
    name="left_hip_pitch_link">
    <inertial>
      <origin
        xyz="0.00276 0.06024 0.00021"
        rpy="0 0 0" />
      <mass
        value="0.98538" />
      <inertia
        ixx="0.00138"
        ixy="0.0"
        ixz="2E-5"
        iyy="0.00094"
        iyz="1E-5"
        izz="0.00109" />
    </inertial>
    <visual>
      <origin
        xyz="0 0 0"
        rpy="0 0 0" />
      <geometry>
        <mesh
          filename="meshes/left_hip_pitch_link.STL" />
      </geometry>
      <material
        name="">
        <color
          rgba="0.75294 0.75294 0.75294 1" />
      </material>
    </visual>
    <collision>
      <origin
        xyz="0 0 0"
        rpy="0 0 0" />
      <geometry>
        <mesh
          filename="meshes/left_hip_pitch_link.STL" />
      </geometry>
    </collision>
  </link>
  <joint
    name="left_hip_pitch_joint"
    type="revolute">
    <origin
      xyz="0 0.068943 -0.08099"
      rpy="-0.43633 0 0" />
    <parent
      link="pelvis" />
    <child
      link="left_hip_pitch_link" />
    <axis
      xyz="0 1 0" />
    <limit
      lower="-1.57"
      upper="1.57"
      effort="66"
      velocity="20.42" />
  </joint>

  <link
    name="left_hip_roll_link">
    <inertial>
      <origin
        xyz="-0.00137 -0.00017 -0.07331"
        rpy="0 0 0" />
      <mass
        value="1.2243" />
      <inertia
        ixx="0.00228"
        ixy="0.0"
        ixz="-0.00013"
        iyy="0.00272"
        iyz="0.0"
        izz="0.00185" />
    </inertial>
    <visual>
      <origin
        xyz="0 0 0"
        rpy="0 0 0" />
      <geometry>
        <mesh
          filename="meshes/hip_roll_link.STL" />
      </geometry>
      <material
        name="">
        <color
          rgba="0.75294 0.75294 0.75294 1" />
      </material>
    </visual>
    <collision>
      <origin
        xyz="0 0 0"
        rpy="0 0 0" />
      <geometry>
        <mesh
          filename="meshes/hip_roll_link.STL" />
      </geometry>
    </collision>
  </link>
  <joint
    name="left_hip_roll_joint"
    type="revolute">
    <origin
      xyz="0.0058 0.065 0"
      rpy="0.43633 0 0" />
    <parent
      link="left_hip_pitch_link" />
    <child
      link="left_hip_roll_link" />
    <axis
      xyz="1 0 0" />
    <limit
      lower="-0.52"
      upper="2.6"
      effort="66"
      velocity="20.42" />
  </joint>

   <link
    name="left_hip_yaw_link">
    <inertial>
      <origin
        xyz="0.00098 0.01704 -0.09315"
        rpy="0 0 0" />
      <mass
        value="2.225" />
      <inertia
        ixx="0.00784"
        ixy="-4E-05"
        ixz="-0.0002"
        iyy="0.00935"
        iyz="-0.0006"
        izz="0.00334" />
    </inertial>
    <visual>
      <origin
        xyz="0 0 0"
        rpy="0 0 0" />
      <geometry>
        <mesh
          filename="meshes/left_hip_yaw_link.STL" />
      </geometry>
      <material
        name="">
        <color
          rgba="0.75294 0.75294 0.75294 1" />
      </material>
    </visual>
    <collision>
      <origin
        xyz="0 0 0"
        rpy="0 0 0" />
      <geometry>
        <mesh
          filename="meshes/left_hip_yaw_link.STL" />
      </geometry>
    </collision>
  </link>
  <joint
    name="left_hip_yaw_joint"
    type="revolute">
    <origin
      xyz="0 0 -0.115"
      rpy="0 0 0" />
    <parent
      link="left_hip_roll_link" />
    <child
      link="left_hip_yaw_link" />
    <axis
      xyz="0 0 1" />
    <limit
      lower="-1.57"
      upper="1.57"
      effort="66"
      velocity="20.42" />
  </joint>

 <link
    name="left_knee_link">
    <inertial>
      <origin
        xyz="0.01246 0.0 -0.1525"
        rpy="0 0 0" />
      <mass
        value="1.533" />
      <inertia
        ixx="0.01312"
        ixy="0.0"
        ixz="-0.00024"
        iyy="0.01339"
        iyz="-0.00007"
        izz="0.00098" />
    </inertial>
    <visual>
      <origin
        xyz="0 0 0"
        rpy="0 0 0" />
      <geometry>
        <mesh
          filename="meshes/left_knee_link.STL" />
      </geometry>
      <material
        name="">
        <color
          rgba="0.75294 0.75294 0.75294 1" />
      </material>
    </visual>
    <!-- <collision>
      <origin
        xyz="0 0 0"
        rpy="0 0 0" />
      <geometry>
        <mesh
          filename="meshes/left_knee_link.STL" />
      </geometry>
    </collision> -->
  </link>
  <joint
    name="left_knee_joint"
    type="revolute">
    <origin
      xyz="0 0 -0.235"
      rpy="0 0 0" />
    <parent
      link="left_hip_yaw_link" />
    <child
      link="left_knee_link" />
    <axis
      xyz="0 1 0" />
    <limit
      lower="0.15"
      upper="2.12"
      effort="120"
      velocity="21" />
  </joint>

    <link
    name="left_ankle_pitch_link">
    <inertial>
      <origin
        xyz="0 4.7735E-05 -0.0098018"
        rpy="0 0 0" />
      <mass
        value="0.030932" />
      <inertia
        ixx="8E-05"
        ixy="0.0"
        ixz="0.0"
        iyy="7E-05"
        iyz="0.0"
        izz="2E-05" />
    </inertial>
  </link>
  <joint
    name="left_ankle_pitch_joint"
    type="revolute">
    <origin
      xyz="0 0 -0.35"
      rpy="0 0 0" />
    <parent
      link="left_knee_link" />
    <child
      link="left_ankle_pitch_link" />
    <axis
      xyz="0 1 0" />
    <limit
      lower="-0.78"
      upper="0.78"
      effort="38"
      velocity="43" />
  </joint>
  <link
    name="left_ankle_roll_link">
    <inertial>
      <origin
        xyz="0.000847 0.0 -0.01996"
        rpy="0 0 0" />
      <mass
        value="0.246" />
      <inertia
        ixx="0.000073"
        ixy="0.0"
        ixz="-0.000031"
        iyy="0.000544"
        iyz="0.0"
        izz="0.000569" />
    </inertial>
    <visual>
      <origin
        xyz="0 0 0"
        rpy="0 0 0" />
      <geometry>
        <mesh
          filename="meshes/ankle_roll_link.STL" />
      </geometry>
      <material
        name="">
        <color
          rgba="0.75294 0.75294 0.75294 1" />
      </material>
    </visual>
    <collision>
      <origin
        xyz="0 0 0"
        rpy="0 0 0" />
      <geometry>
        <mesh
          filename="meshes/ankle_roll_link.STL" />
      </geometry>
    </collision>
  </link>
  <joint
    name="left_ankle_roll_joint"
    type="revolute">
    <origin
      xyz="0 0 -0.02"
      rpy="0 0 0" />
    <parent
      link="left_ankle_pitch_link" />
    <child
      link="left_ankle_roll_link" />
    <axis
      xyz="1 0 0" />
    <limit
      lower="-0.27"
      upper="0.27"
      effort="38"
      velocity="43" />
  </joint>
  <link
    name="right_hip_pitch_link">
    <inertial>
      <origin
        xyz="0.00276 -0.06024 -0.00021"
        rpy="0 0 0" />
      <mass
        value="0.9853" />
      <inertia
        ixx="0.00138"
        ixy="-2E-5"
        ixz="0.0"
        iyy="0.00094"
        iyz="0.00001"
        izz="0.00109" />
    </inertial>
    <visual>
      <origin
        xyz="0 0 0"
        rpy="0 0 0" />
      <geometry>
        <mesh
          filename="meshes/right_hip_pitch_link.STL" />
      </geometry>
      <material
        name="">
        <color
          rgba="0.752941176470588 0.752941176470588 0.752941176470588 1" />
      </material>
    </visual>
    <collision>
      <origin
        xyz="0 0 0"
        rpy="0 0 0" />
      <geometry>
        <mesh
          filename="meshes/right_hip_pitch_link.STL" />
      </geometry>
    </collision>
  </link>
  <joint
    name="right_hip_pitch_joint"
    type="revolute">
    <origin
      xyz="0 -0.069043 -0.08099"
      rpy="0.43633 0 0" />
    <parent
      link="pelvis" />
    <child
      link="right_hip_pitch_link" />
    <axis
      xyz="0 1 0" />
    <limit
      lower="-1.57"
      upper="1.57"
      effort="66"
      velocity="20.42" />
  </joint>

  <link
    name="right_hip_roll_link">
    <inertial>
    <origin
        xyz="-0.00137 -0.00017 -0.07331"
        rpy="0 0 0" />
      <mass
        value="1.2243" />
      <inertia
        ixx="0.00228"
        ixy="0.0"
        ixz="-0.00013"
        iyy="0.00272"
        iyz="0.0"
        izz="0.00185" />
    </inertial>
    <visual>
      <origin
        xyz="0 0 0"
        rpy="0 0 0" />
      <geometry>
        <mesh
          filename="meshes/hip_roll_link.STL" />
      </geometry>
      <material
        name="">
        <color
          rgba="0.752941176470588 0.752941176470588 0.752941176470588 1" />
      </material>
    </visual>
    <collision>
      <origin
        xyz="0 0 0"
        rpy="0 0 0" />
      <geometry>
        <mesh
          filename="meshes/hip_roll_link.STL" />
      </geometry>
    </collision>
  </link>
  <joint
    name="right_hip_roll_joint"
    type="revolute">
    <origin
      xyz="0.0058 -0.065 0"
      rpy="-0.43633 0 0" />
    <parent
      link="right_hip_pitch_link" />
    <child
      link="right_hip_roll_link" />
    <axis
      xyz="1 0 0" />
    <limit
      lower="-2.6"
      upper="0.52"
      effort="66"
      velocity="20.42" />
  </joint>

 <link
    name="right_hip_yaw_link">
    <inertial>
      <origin
        xyz="0.00163 -0.01704 -0.09426"
        rpy="0 0 0" />
      <mass
        value="2.225" />
      <inertia
        ixx="0.00772"
        ixy="6E-05"
        ixz="-0.00014"
        iyy="0.00926"
        iyz="-0.00054"
        izz="0.00335" />
    </inertial>
    <visual>
      <origin
        xyz="0 0 0"
        rpy="0 0 0" />
      <geometry>
        <mesh
          filename="meshes/right_hip_yaw_link.STL" />
      </geometry>
      <material
        name="">
        <color
          rgba="0.752941176470588 0.752941176470588 0.752941176470588 1" />
      </material>
    </visual>
    <collision>
      <origin
        xyz="0 0 0"
        rpy="0 0 0" />
      <geometry>
        <mesh
          filename="meshes/right_hip_yaw_link.STL" />
      </geometry>
    </collision>
  </link>
  <joint
    name="right_hip_yaw_joint"
    type="revolute">
    <origin
      xyz="0 0 -0.115"
      rpy="0 0 0" />
    <parent
      link="right_hip_roll_link" />
    <child
      link="right_hip_yaw_link" />
    <axis
      xyz="0 0 1" />
    <limit
      lower="-1.57"
      upper="1.57"
      effort="66"
      velocity="20.42" />
  </joint>
  <link
    name="right_knee_link">
    <inertial>
      <origin
        xyz="0.01246 0.0 -0.1525"
        rpy="0 0 0" />
      <mass
        value="1.533" />
      <inertia
        ixx="0.01312"
        ixy="0.0"
        ixz="-0.00024"
        iyy="0.01339"
        iyz="-0.00007"
        izz="0.00098" />
    </inertial>
    <visual>
      <origin
        xyz="0 0 0"
        rpy="0 0 0" />
      <geometry>
        <mesh
          filename="meshes/right_knee_link.STL" />
      </geometry>
      <material
        name="">
        <color
          rgba="0.752941176470588 0.752941176470588 0.752941176470588 1" />
      </material>
    </visual>
    <!-- <collision>
      <origin
        xyz="0 0 0"
        rpy="0 0 0" />
      <geometry>
        <mesh
          filename="meshes/right_knee_link.STL" />
      </geometry>
    </collision> -->
  </link>
  <joint
    name="right_knee_joint"
    type="revolute">
    <origin
      xyz="0 0 -0.235"
      rpy="0 0 0" />
    <parent
      link="right_hip_yaw_link" />
    <child
      link="right_knee_link" />
    <axis
      xyz="0 1 0" />
    <limit
      lower="0.15"
      upper="2.12"
      effort="120"
      velocity="21" />
  </joint>
  <link
    name="right_ankle_pitch_link">
   <inertial>
      <origin
        xyz="0 4.7735E-05 -0.0098018"
        rpy="0 0 0" />
      <mass
        value="0.030932" />
      <inertia
        ixx="8E-05"
        ixy="0.0"
        ixz="0.0"
        iyy="7E-05"
        iyz="0.0"
        izz="2E-05" />
    </inertial>
  </link>
  <joint
    name="right_ankle_pitch_joint"
    type="revolute">
    <origin
      xyz="0 0 -0.35"
      rpy="0 0 0" />
    <parent
      link="right_knee_link" />
    <child
      link="right_ankle_pitch_link" />
    <axis
      xyz="0 1 0" />
    <limit
      lower="-0.78"
      upper="0.78"
      effort="38"
      velocity="43" />
  </joint>
  <link
    name="right_ankle_roll_link">
    <inertial>
      <origin
        xyz="0.000847 0.0 -0.01996"
        rpy="0 0 0" />
      <mass
        value="0.246" />
      <inertia
        ixx="0.0001713"
        ixy="0.0"
        ixz="-0.0000724"
        iyy="0.0006569"
        iyz="0.0"
        izz="0.0005866" />
    </inertial>
    <visual>
      <origin
        xyz="0 0 0"
        rpy="0 0 0" />
      <geometry>
        <mesh
          filename="meshes/ankle_roll_link.STL" />
      </geometry>
      <material
        name="">
        <color
          rgba="0.752941176470588 0.752941176470588 0.752941176470588 1" />
      </material>
    </visual>
    <collision>
      <origin
        xyz="0 0 0"
        rpy="0 0 0" />
      <geometry>
        <mesh
          filename="meshes/ankle_roll_link.STL" />
      </geometry>
    </collision>
  </link>
  <joint
    name="right_ankle_roll_joint"
    type="revolute">
    <origin
      xyz="0 0 -0.02"
      rpy="0 0 0" />
    <parent
      link="right_ankle_pitch_link" />
    <child
      link="right_ankle_roll_link" />
    <axis
      xyz="1 0 0" />
    <limit
      lower="-0.27"
      upper="0.27"
      effort="38"
      velocity="43" />
  </joint> 

</robot>