<mujoco model="m1">
  <compiler angle="radian" meshdir="meshes/"/>

  <asset>
    <mesh name="pelvis" file="pelvis.STL"/>
    <mesh name="left_hip_pitch_link" file="left_hip_pitch_link.STL"/>
    <mesh name="hip_roll_link" file="hip_roll_link.STL"/>
    <mesh name="left_hip_yaw_link" file="left_hip_yaw_link.STL"/>
    <mesh name="left_knee_link" file="left_knee_link.STL"/>
    <mesh name="ankle_roll_link" file="ankle_roll_link.STL"/>
    <mesh name="right_hip_pitch_link" file="right_hip_pitch_link.STL"/>
    <mesh name="right_hip_yaw_link" file="right_hip_yaw_link.STL"/>
    <mesh name="right_knee_link" file="right_knee_link.STL"/>
  </asset>

  <worldbody>
    <body name="pelvis">
      <inertial pos="-5e-05 -6e-05 -0.06266" quat="0.491943 0.491852 -0.508952 0.506993" mass="3.2817" diaginertia="0.0137903 0.0134797 0.00851996"/>
      <joint name="floating_base_joint" type="free" limited="false" actuatorfrclimited="false"/>
      <geom type="mesh" contype="0" conaffinity="0" group="1" density="0" rgba="0.752941 0.752941 0.752941 1" mesh="pelvis"/>
      <geom type="mesh" rgba="0.752941 0.752941 0.752941 1" mesh="pelvis"/>
      <body name="left_hip_pitch_link" pos="0 0.068943 -0.08099" quat="0.976296 -0.216438 0 0">
        <inertial pos="0.00276 0.06024 0.00021" quat="0.729888 0.682705 -0.0245092 0.0239885" mass="0.98538" diaginertia="0.00138137 0.00108929 0.000939332"/>
        <joint name="left_hip_pitch_joint" pos="0 0 0" axis="0 1 0" range="-1.57 1.57" actuatorfrcrange="-66 66"/>
        <geom type="mesh" contype="0" conaffinity="0" group="1" density="0" rgba="0.75294 0.75294 0.75294 1" mesh="left_hip_pitch_link"/>
        <geom type="mesh" rgba="0.75294 0.75294 0.75294 1" mesh="left_hip_pitch_link"/>
        <body name="left_hip_roll_link" pos="0.0058 0.065 0" quat="0.976296 0.216438 0 0">
          <inertial pos="-0.00137 -0.00017 -0.07331" quat="0.700582 0.095841 0.095841 0.700582" mass="1.2243" diaginertia="0.00272 0.00231625 0.00181375"/>
          <joint name="left_hip_roll_joint" pos="0 0 0" axis="1 0 0" range="-0.52 2.6" actuatorfrcrange="-66 66"/>
          <geom type="mesh" contype="0" conaffinity="0" group="1" density="0" rgba="0.75294 0.75294 0.75294 1" mesh="hip_roll_link"/>
          <geom type="mesh" rgba="0.75294 0.75294 0.75294 1" mesh="hip_roll_link"/>
          <body name="left_hip_yaw_link" pos="0 0 -0.115">
            <inertial pos="0.00098 0.01704 -0.09315" quat="0.702285 -0.0188635 0.0506672 0.70984" mass="2.225" diaginertia="0.00940957 0.00784876 0.00327167"/>
            <joint name="left_hip_yaw_joint" pos="0 0 0" axis="0 0 1" range="-1.57 1.57" actuatorfrcrange="-66 66"/>
            <geom type="mesh" contype="0" conaffinity="0" group="1" density="0" rgba="0.75294 0.75294 0.75294 1" mesh="left_hip_yaw_link"/>
            <geom type="mesh" rgba="0.75294 0.75294 0.75294 1" mesh="left_hip_yaw_link"/>
            <body name="left_knee_link" pos="0 0 -0.235">
              <inertial pos="0.01246 0 -0.1525" quat="0.708888 0.00496943 0.00899163 0.705246" mass="1.533" diaginertia="0.0133904 0.0131247 0.000974863"/>
              <joint name="left_knee_joint" pos="0 0 0" axis="0 1 0" range="0.15 2.12" actuatorfrcrange="-120 120"/>
              <geom type="mesh" contype="0" conaffinity="0" group="1" density="0" rgba="0.75294 0.75294 0.75294 1" mesh="left_knee_link"/>
              <body name="left_ankle_pitch_link" pos="0 0 -0.35">
                <inertial pos="0 4.7735e-05 -0.0098018" mass="0.030932" diaginertia="8e-05 7e-05 2e-05"/>
                <joint name="left_ankle_pitch_joint" pos="0 0 0" axis="0 1 0" range="-0.78 0.78" actuatorfrcrange="-38 38"/>
                <body name="left_ankle_roll_link" pos="0 0 -0.02">
                  <inertial pos="0.000847 0 -0.01996" quat="0 0.684786 0 0.728745" mass="0.246" diaginertia="0.00057093 0.000544 7.107e-05"/>
                  <joint name="left_ankle_roll_joint" pos="0 0 0" axis="1 0 0" range="-0.27 0.27" actuatorfrcrange="-38 38"/>
                  <geom type="mesh" contype="0" conaffinity="0" group="1" density="0" rgba="0.75294 0.75294 0.75294 1" mesh="ankle_roll_link"/>
                  <geom type="mesh" rgba="0.75294 0.75294 0.75294 1" mesh="ankle_roll_link"/>
                </body>
              </body>
            </body>
          </body>
        </body>
      </body>
      <body name="right_hip_pitch_link" pos="0 -0.069043 -0.08099" quat="0.976296 0.216438 0 0">
        <inertial pos="0.00276 -0.06024 -0.00021" quat="0.729789 0.683296 -0.0149324 -0.0170892" mass="0.9853" diaginertia="0.00138091 0.00109066 0.000938434"/>
        <joint name="right_hip_pitch_joint" pos="0 0 0" axis="0 1 0" range="-1.57 1.57" actuatorfrcrange="-66 66"/>
        <geom type="mesh" contype="0" conaffinity="0" group="1" density="0" rgba="0.752941 0.752941 0.752941 1" mesh="right_hip_pitch_link"/>
        <geom type="mesh" rgba="0.752941 0.752941 0.752941 1" mesh="right_hip_pitch_link"/>
        <body name="right_hip_roll_link" pos="0.0058 -0.065 0" quat="0.976296 -0.216438 0 0">
          <inertial pos="-0.00137 -0.00017 -0.07331" quat="0.700582 0.095841 0.095841 0.700582" mass="1.2243" diaginertia="0.00272 0.00231625 0.00181375"/>
          <joint name="right_hip_roll_joint" pos="0 0 0" axis="1 0 0" range="-2.6 0.52" actuatorfrcrange="-66 66"/>
          <geom type="mesh" contype="0" conaffinity="0" group="1" density="0" rgba="0.752941 0.752941 0.752941 1" mesh="hip_roll_link"/>
          <geom type="mesh" rgba="0.752941 0.752941 0.752941 1" mesh="hip_roll_link"/>
          <body name="right_hip_yaw_link" pos="0 0 -0.115">
            <inertial pos="0.00163 -0.01704 -0.09426" quat="0.722679 -0.0220708 0.0420168 0.689553" mass="2.225" diaginertia="0.00931223 0.00772076 0.003297"/>
            <joint name="right_hip_yaw_joint" pos="0 0 0" axis="0 0 1" range="-1.57 1.57" actuatorfrcrange="-66 66"/>
            <geom type="mesh" contype="0" conaffinity="0" group="1" density="0" rgba="0.752941 0.752941 0.752941 1" mesh="right_hip_yaw_link"/>
            <geom type="mesh" rgba="0.752941 0.752941 0.752941 1" mesh="right_hip_yaw_link"/>
            <body name="right_knee_link" pos="0 0 -0.235">
              <inertial pos="0.01246 0 -0.1525" quat="0.708888 0.00496943 0.00899163 0.705246" mass="1.533" diaginertia="0.0133904 0.0131247 0.000974863"/>
              <joint name="right_knee_joint" pos="0 0 0" axis="0 1 0" range="0.15 2.12" actuatorfrcrange="-120 120"/>
              <geom type="mesh" contype="0" conaffinity="0" group="1" density="0" rgba="0.752941 0.752941 0.752941 1" mesh="right_knee_link"/>
              <body name="right_ankle_pitch_link" pos="0 0 -0.35">
                <inertial pos="0 4.7735e-05 -0.0098018" mass="0.030932" diaginertia="8e-05 7e-05 2e-05"/>
                <joint name="right_ankle_pitch_joint" pos="0 0 0" axis="0 1 0" range="-0.78 0.78" actuatorfrcrange="-38 38"/>
                <body name="right_ankle_roll_link" pos="0 0 -0.02">
                  <inertial pos="0.000847 0 -0.01996" quat="0.540129 0.456356 0.456356 0.540129" mass="0.246" diaginertia="0.0006569 0.00059886 0.00015904"/>
                  <joint name="right_ankle_roll_joint" pos="0 0 0" axis="1 0 0" range="-0.27 0.27" actuatorfrcrange="-38 38"/>
                  <geom type="mesh" contype="0" conaffinity="0" group="1" density="0" rgba="0.752941 0.752941 0.752941 1" mesh="ankle_roll_link"/>
                  <geom type="mesh" rgba="0.752941 0.752941 0.752941 1" mesh="ankle_roll_link"/>
                </body>
              </body>
            </body>
          </body>
        </body>
      </body>
    </body>
  </worldbody>
</mujoco>
